<?xml version="1.0" ?>
<!-- =================================================================================== -->
<!-- |    This document was autogenerated by xacro from /home/etudiant/catkin_ws/src/motoman/motoman_hc10_support/urdf/hc10.xacro | -->
<!-- |    EDITING THIS FILE BY HAND IS NOT RECOMMENDED                                 | -->
<!-- =================================================================================== -->
<robot name="motoman_hc10">
    <!-- link list -->
    <link name="world" />
    <link name="base_link">
        
<inertial>
            <origin rpy="0 0 0" xyz="0 0 0" />
            <mass value="0.1" />
            <inertia ixx="0.03" ixy="0.03" ixz="0.03" iyy="0.0" iyz="0.0" izz="0.0" />
        </inertial>

        <visual>
            <geometry>
                <mesh filename="package://motoman_hc10_support/meshes/hc10/visual/base_link.dae" />
            </geometry>
            <material name="">
                <color rgba="0.12941176470588237 0.14901960784313725 0.7490196078431373 1.0" />
            </material>
        </visual>
        <collision>
            <geometry>
                <mesh filename="package://motoman_hc10_support/meshes/hc10/collision/base_link.stl" />
            </geometry>
        </collision>
    </link>
    <link name="link_1_s">
        
<inertial>
            <origin rpy="0 0 0" xyz="0 0 0" />
            <mass value="0.1" />
            <inertia ixx="0.03" ixy="0.03" ixz="0.03" iyy="0.0" iyz="0.0" izz="0.0" />
        </inertial>

        <visual>
            <geometry>
                <mesh filename="package://motoman_hc10_support/meshes/hc10/visual/link_1_s.dae" />
            </geometry>
            <material name="">
                <color rgba="0.12941176470588237 0.14901960784313725 0.7490196078431373 1.0" />
            </material>
        </visual>
        <collision>
            <geometry>
                <mesh filename="package://motoman_hc10_support/meshes/hc10/collision/link_1_s.stl" />
            </geometry>
        </collision>
    </link>
    <link name="link_2_l">
        
<inertial>
            <origin rpy="0 0 0" xyz="0 0 0" />
            <mass value="0.1" />
            <inertia ixx="0.03" ixy="0.03" ixz="0.03" iyy="0.0" iyz="0.0" izz="0.0" />
        </inertial>

        <visual>
            <geometry>
                <mesh filename="package://motoman_hc10_support/meshes/hc10/visual/link_2_l.dae" />
            </geometry>
            <material name="">
                <color rgba="0.12941176470588237 0.14901960784313725 0.7490196078431373 1.0" />
            </material>
        </visual>
        <collision>
            <geometry>
                <mesh filename="package://motoman_hc10_support/meshes/hc10/collision/link_2_l.stl" />
            </geometry>
        </collision>
        hc10_macro
    </link>
    <link name="link_3_u">
        
<inertial>
            <origin rpy="0 0 0" xyz="0 0 0" />
            <mass value="0.1" />
            <inertia ixx="0.03" ixy="0.03" ixz="0.03" iyy="0.0" iyz="0.0" izz="0.0" />
        </inertial>

        <visual>
            <geometry>
                <mesh filename="package://motoman_hc10_support/meshes/hc10/visual/link_3_u.dae" />
            </geometry>
            <material name="">
                <color rgba="0.12941176470588237 0.14901960784313725 0.7490196078431373 1.0" />
            </material>
        </visual>
        <collision>
            <geometry>
                <mesh filename="package://motoman_hc10_support/meshes/hc10/collision/link_3_u.stl" />
            </geometry>
        </collision>
    </link>
    <link name="link_4_r">
        
<inertial>
            <origin rpy="0 0 0" xyz="0 0 0" />
            <mass value="0.1" />
            <inertia ixx="0.03" ixy="0.03" ixz="0.03" iyy="0.0" iyz="0.0" izz="0.0" />
        </inertial>

        <visual>
            <geometry>
                <mesh filename="package://motoman_hc10_support/meshes/hc10/visual/link_4_r.dae" />
            </geometry>
            <material name="">
                <color rgba="0.12941176470588237 0.14901960784313725 0.7490196078431373 1.0" />
            </material>
        </visual>
        <collision>
            <geometry>
                <mesh filename="package://motoman_hc10_support/meshes/hc10/collision/link_4_r.stl" />
            </geometry>
        </collision>
    </link>
    <link name="link_5_b">
        
<inertial>
            <origin rpy="0 0 0" xyz="0 0 0" />
            <mass value="0.1" />
            <inertia ixx="0.03" ixy="0.03" ixz="0.03" iyy="0.0" iyz="0.0" izz="0.0" />
        </inertial>

        <visual>
            <geometry>
                <mesh filename="package://motoman_hc10_support/meshes/hc10/visual/link_5_b.dae" />
            </geometry>
            <material name="">
                <color rgba="0.12941176470588237 0.14901960784313725 0.7490196078431373 1.0" />
            </material>
        </visual>
        <collision>
            <geometry>
                <mesh filename="package://motoman_hc10_support/meshes/hc10/collision/link_5_b.stl" />
            </geometry>
        </collision>
    </link>
    <link name="link_6_t">
        
<inertial>
            <origin rpy="0 0 0" xyz="0 0 0" />
            <mass value="0.1" />
            <inertia ixx="0.03" ixy="0.03" ixz="0.03" iyy="0.0" iyz="0.0" izz="0.0" />
        </inertial>

        <visual>
            <geometry>
                <mesh filename="package://motoman_hc10_support/meshes/hc10/visual/link_6_t.dae" />
            </geometry>
            <material name="">
                <color rgba="0.12941176470588237 0.14901960784313725 0.7490196078431373 1.0" />
            </material>
        </visual>
        <collision>
            <geometry>
                <mesh filename="package://motoman_hc10_support/meshes/hc10/collision/link_6_t.stl" />
            </geometry>
        </collision>
    </link>
    <link name="tool0" />
    <!-- end of link list -->
    <!-- joint list -->
    <joint name="world_fixed" type="fixed">
        <parent link="world" />
        <child link="base_link" />
        <origin rpy="0 0 0" xyz="0.1 0.1 0.5" />
    </joint>
    <joint name="joint_1_s" type="revolute">
        <parent link="base_link" />
        <child link="link_1_s" />
        <origin rpy="0 0 0" xyz="0 0 0.275" />
        <axis xyz="0 0 1" />
        <limit effort="368.48" lower="-3.141592653589793" upper="3.141592653589793" velocity="2.2689280275926285" />
        <dynamics damping="1" />
    </joint>
    <joint name="joint_2_l" type="revolute">
        <parent link="link_1_s" />
        <child link="link_2_l" />
        <origin rpy="0 0 0" xyz="0 0 0" />
        <axis xyz="0 1 0" />
        <limit effort="368.48" lower="-3.141592653589793" upper="3.141592653589793" velocity="2.2689280275926285" />
        <dynamics damping="1" />
    </joint>
    <joint name="joint_3_u" type="revolute">
        <parent link="link_2_l" />
        <child link="link_3_u" />
        <origin rpy="0 0 0" xyz="0 0 0.700" />
        <axis xyz="0 -1 0" />
        <limit effort="141.12" lower="-0.08726646259971647" upper="6.19591884457987" velocity="3.141592653589793" />
        <dynamics damping="1" />
    </joint>
    <joint name="joint_4_r" type="revolute">
        <parent link="link_3_u" />
        <child link="link_4_r" />
        <origin rpy="0 0 0" xyz="0 0 -0.500" />
        <axis xyz="0 0 1" />
        <limit effort="39.20" lower="-3.141592653589793" upper="3.141592653589793" velocity="3.141592653589793" />
        <dynamics damping="1" />
    </joint>
    <joint name="joint_5_b" type="revolute">
        <parent link="link_4_r" />
        <child link="link_5_b" />
        <origin rpy="0 0 0" xyz="0 0.162 0" />
        <axis xyz="0 -1 0" />
        <limit effort="31.36" lower="-3.141592653589793" upper="3.141592653589793" velocity="4.363323129985824" />
        <dynamics damping="1" />
    </joint>
    <joint name="joint_6_t" type="revolute">
        <parent link="link_5_b" />
        <child link="link_6_t" />
        <origin rpy="0 0 0" xyz="0 0 0" />
        <axis xyz="0 0 1" />
        <limit effort="31.36" lower="-3.141592653589793" upper="3.141592653589793" velocity="4.363323129985824" />
        <dynamics damping="1" />
    </joint>
    <joint name="joint_6_t-tool0" type="fixed">
        <origin rpy="3.141592653589793 0 0" xyz="0 0 -0.130" />
        <parent link="link_6_t" />
        <child link="tool0" />
    </joint>
    <!-- end of joint list -->
    <!-- ROS base_link to Robot Manufacturer World Coordinates transform -->
    <gazebo reference="box_fixed">
        <material>Gazebo/Blue</material>
        <mu1>0.2</mu1>
        <mu2>0.2</mu2>
    </gazebo>
    <gazebo reference="base_link">
        <material>Gazebo/White</material>
        <mu1>0.2</mu1>
        <mu2>0.2</mu2>
    </gazebo>
    <gazebo reference="link_1_s">
        <material>Gazebo/White</material>
        <mu1>0.2</mu1>
        <mu2>0.2</mu2>
    </gazebo>
    <gazebo reference="link_2_l">
        <material>Gazebo/White</material>
        <mu1>0.2</mu1>
        <mu2>0.2</mu2>
    </gazebo>
    <gazebo reference="link_3_u">
        <material>Gazebo/White</material>
        <mu1>0.2</mu1>
        <mu2>0.2</mu2>
    </gazebo>
    <gazebo reference="link_4_r">
        <material>Gazebo/White</material>
        <mu1>0.2</mu1>
        <mu2>0.2</mu2>
    </gazebo>
    <gazebo reference="link_5_b">
        <material>Gazebo/White</material>
        <mu1>0.2</mu1>
        <mu2>0.2</mu2>
    </gazebo>
    <gazebo reference="link_6_t">
        <material>Gazebo/White</material>
        <mu1>0.2</mu1>
        <mu2>0.2</mu2>
    </gazebo>
    <gazebo reference="tool0">
        <material>Gazebo/White</material>
        <mu1>0.2</mu1>
        <mu2>0.2</mu2>
    </gazebo>
    <gazebo reference="camera_link">
        <material>Gazebo/White</material>
        <mu1>0.2</mu1>
        <mu2>0.2</mu2>
    </gazebo>
    
<transmission name="_tran_1">
        <type>transmission_interface/SimpleTransmission</type>
        <joint name="joint_1_s">
            <hardwareInterface>hardware_interface/EffortJointInterface</hardwareInterface>
        </joint>
        <actuator name="_motor_1">
            <hardwareInterface>hardware_interface/EffortJointInterface</hardwareInterface>
            <mechanicalReduction>1</mechanicalReduction>
        </actuator>
    </transmission>
    <transmission name="_tran_2">
        <type>transmission_interface/SimpleTransmission</type>
        <joint name="joint_2_l">
            <hardwareInterface>hardware_interface/EffortJointInterface</hardwareInterface>
        </joint>
        <actuator name="_motor_2">
            <hardwareInterface>hardware_interface/EffortJointInterface</hardwareInterface>
            <mechanicalReduction>1</mechanicalReduction>
        </actuator>
    </transmission>
    <transmission name="_tran_3">
        <type>transmission_interface/SimpleTransmission</type>
        <joint name="joint_3_u">
            <hardwareInterface>hardware_interface/EffortJointInterface</hardwareInterface>
        </joint>
        <actuator name="_motor_3">
            <hardwareInterface>hardware_interface/EffortJointInterface</hardwareInterface>
            <mechanicalReduction>1</mechanicalReduction>
        </actuator>
    </transmission>
    <transmission name="_tran_4">
        <type>transmission_interface/SimpleTransmission</type>
        <joint name="joint_4_r">
            <hardwareInterface>hardware_interface/EffortJointInterface</hardwareInterface>
        </joint>
        <actuator name="_motor_4">
            <hardwareInterface>hardware_interface/EffortJointInterface</hardwareInterface>
            <mechanicalReduction>1</mechanicalReduction>
        </actuator>
    </transmission>
    <transmission name="_tran_5">
        <type>transmission_interface/SimpleTransmission</type>
        <joint name="joint_5_b">
            <hardwareInterface>hardware_interface/EffortJointInterface</hardwareInterface>
        </joint>
        <actuator name="_motor_5">
            <hardwareInterface>hardware_interface/EffortJointInterface</hardwareInterface>
            <mechanicalReduction>1</mechanicalReduction>
        </actuator>
    </transmission>
    <transmission name="_tran_6">
        <type>transmission_interface/SimpleTransmission</type>
        <joint name="joint_6_t">
            <hardwareInterface>hardware_interface/EffortJointInterface</hardwareInterface>
        </joint>
        <actuator name="_motor_6">
            <hardwareInterface>hardware_interface/EffortJointInterface</hardwareInterface>
            <mechanicalReduction>1</mechanicalReduction>
        </actuator>
    </transmission>
    <gazebo>
        <plugin filename="libgazebo_ros_control.so" name="gazebo_ros_control" />
    </gazebo>
    <!-- Attach Kinect -->
    <joint name="camera_joint" type="fixed">
        <origin rpy="0 0 0" xyz="0 0 0" />
        <child link="camera_link" />
        <parent link="tool0" />
        <axis rpy="0 0 0" xyz="0 0 0" />
        <limit effort="10000" velocity="1000" />
        <dynamics damping="1.0" friction="1.0" />
    </joint>
    <link name="camera_link">
        <visual>
            <geometry>
                <box size="0.010 0.03 0.03" />
            </geometry>
        </visual>
    </link>
    <gazebo reference="camera_link">
        <sensor name="kinect_camera" type="depth">
            <update_rate>20</update_rate>
            <camera>
                <horizontal_fov>1.047198</horizontal_fov>
                <image>
                    <width>640</width>
                    <height>480</height>
                    <format>B8G8R8</format>
                </image>
                <clip>
                    <near>0.05</near>
                    <far>3</far>
                </clip>
            </camera>
            <plugin filename="libgazebo_ros_openni_kinect.so" name="kinect_controller">
                <baseline>0.1</baseline>
                <alwaysOn>true</alwaysOn>
                <updateRate>10</updateRate>
                <cameraName>camera_ir</cameraName>
                <imageTopicName>/camera/color/image_raw</imageTopicName>
                <cameraInfoTopicName>/camera/color/camera_info</cameraInfoTopicName>
                <depthImageTopicName>/camera/depth/image_raw</depthImageTopicName>
                <depthImageCameraInfoTopicName>/camera/depth/camera_info</depthImageCameraInfoTopicName>
                <pointCloudTopicName>/camera/depth/points</pointCloudTopicName>
                <frameName>camera_depth_optical_frame</frameName>
                <distortion_k1>0.0</distortion_k1>
                <distortion_k2>0.0</distortion_k2>
                <distortion_k3>0.0</distortion_k3>
                <distortion_t1>0.0</distortion_t1>
                <distortion_t2>0.0</distortion_t2>
                <pointCloudCutoff>0.16</pointCloudCutoff>
                <pointCloudCutoffMax>10.0</pointCloudCutoffMax>
            </plugin>
        </sensor>
    </gazebo>
    <!-- end of joint list -->
    <transmission name="trans_joint_1_s">
        <type>transmission_interface/SimpleTransmission</type>
        <joint name="joint_1_s">
            <hardwareInterface>hardware_interface/EffortJointInterface</hardwareInterface>
        </joint>
        <actuator name="joint_1_s_motor">
            <hardwareInterface>hardware_interface/EffortJointInterface</hardwareInterface>
            <mechanicalReduction>1</mechanicalReduction>
        </actuator>
    </transmission>
    <transmission name="trans_joint_2_l">
        <type>transmission_interface/SimpleTransmission</type>
        <joint name="joint_2_l">
            <hardwareInterface>hardware_interface/EffortJointInterface</hardwareInterface>
        </joint>
        <actuator name="joint_2_l_motor">
            <hardwareInterface>hardware_interface/EffortJointInterface</hardwareInterface>
            <mechanicalReduction>1</mechanicalReduction>
        </actuator>
    </transmission>
    <transmission name="trans_joint_3_u">
        <type>transmission_interface/SimpleTransmission</type>
        <joint name="joint_3_u">
            <hardwareInterface>hardware_interface/EffortJointInterface</hardwareInterface>
        </joint>
        <actuator name="joint_3_u_motor">
            <hardwareInterface>hardware_interface/EffortJointInterface</hardwareInterface>
            <mechanicalReduction>1</mechanicalReduction>
        </actuator>
    </transmission>
    <transmission name="trans_joint_4_r">
        <type>transmission_interface/SimpleTransmission</type>
        <joint name="joint_4_r">
            <hardwareInterface>hardware_interface/EffortJointInterface</hardwareInterface>
        </joint>
        <actuator name="joint_4_r_motor">
            <hardwareInterface>hardware_interface/EffortJointInterface</hardwareInterface>
            <mechanicalReduction>1</mechanicalReduction>
        </actuator>
    </transmission>
    <transmission name="trans_joint_5_b">
        <type>transmission_interface/SimpleTransmission</type>
        <joint name="joint_5_b">
            <hardwareInterface>hardware_interface/EffortJointInterface</hardwareInterface>
        </joint>
        <actuator name="joint_5_b_motor">
            <hardwareInterface>hardware_interface/EffortJointInterface</hardwareInterface>
            <mechanicalReduction>1</mechanicalReduction>
        </actuator>
    </transmission>
    <transmission name="trans_joint_6_t">
        <type>transmission_interface/SimpleTransmission</type>
        <joint name="joint_6_t">
            <hardwareInterface>hardware_interface/EffortJointInterface</hardwareInterface>
        </joint>
        <actuator name="joint_6_t_motor">
            <hardwareInterface>hardware_interface/EffortJointInterface</hardwareInterface>
            <mechanicalReduction>1</mechanicalReduction>
        </actuator>
    </transmission>
    <gazebo>
        <plugin name="gazebo_ros_control" filename="libgazebo_ros_control.so">
            <robotNamespace>/</robotNamespace>
        </plugin>
    </gazebo>
</robot>