<?xml version="1.0" ?>
<!-- =================================================================================== -->
<!-- |    This document was autogenerated by xacro from /home/etudiant/catkin_ws/src/motoman/motoman_hc10_support/urdf/hc10.xacro | -->
<!-- |    EDITING THIS FILE BY HAND IS NOT RECOMMENDED                                 | -->
<!-- =================================================================================== -->
<robot name="motoman_hc10">
    <!-- link list -->
    <link name="world" />
    <link name="base_link">
        
<inertial>
            <origin rpy="0 0 0" xyz="0 0 0" />
            <mass value="0.1" />
            <inertia ixx="0.03" ixy="0.03" ixz="0.03" iyy="0.0" iyz="0.0" izz="0.0" />
        </inertial>

        <visual>
            <geometry>
                <mesh filename="package://motoman_hc10_support/meshes/hc10/visual/base_link.dae" />
            </geometry>
            <material name="">
                <color rgba="0.12941176470588237 0.14901960784313725 0.7490196078431373 1.0" />
            </material>
        </visual>
        <collision>
            <geometry>
                <mesh filename="package://motoman_hc10_support/meshes/hc10/collision/base_link.stl" />
            </geometry>
        </collision>
    </link>
    <link name="link_1_s">
        
<inertial>
            <origin rpy="0 0 0" xyz="0 0 0" />
            <mass value="0.1" />
            <inertia ixx="0.03" ixy="0.03" ixz="0.03" iyy="0.0" iyz="0.0" izz="0.0" />
        </inertial>

        <visual>
            <geometry>
                <mesh filename="package://motoman_hc10_support/meshes/hc10/visual/link_1_s.dae" />
            </geometry>
            <material name="">
                <color rgba="0.12941176470588237 0.14901960784313725 0.7490196078431373 1.0" />
            </material>
        </visual>
        <collision>
            <geometry>
                <mesh filename="package://motoman_hc10_support/meshes/hc10/collision/link_1_s.stl" />
            </geometry>
        </collision>
    </link>
    <link name="link_2_l">
        
<inertial>
            <origin rpy="0 0 0" xyz="0 0 0" />
            <mass value="0.1" />
            <inertia ixx="0.03" ixy="0.03" ixz="0.03" iyy="0.0" iyz="0.0" izz="0.0" />
        </inertial>

        <visual>
            <geometry>
                <mesh filename="package://motoman_hc10_support/meshes/hc10/visual/link_2_l.dae" />
            </geometry>
            <material name="">
                <color rgba="0.12941176470588237 0.14901960784313725 0.7490196078431373 1.0" />
            </material>
        </visual>
        <collision>
            <geometry>
                <mesh filename="package://motoman_hc10_support/meshes/hc10/collision/link_2_l.stl" />
            </geometry>
        </collision>
        hc10_macro
    </link>
    <link name="link_3_u">
        
<inertial>
            <origin rpy="0 0 0" xyz="0 0 0" />
            <mass value="0.1" />
            <inertia ixx="0.03" ixy="0.03" ixz="0.03" iyy="0.0" iyz="0.0" izz="0.0" />
        </inertial>

        <visual>
            <geometry>
                <mesh filename="package://motoman_hc10_support/meshes/hc10/visual/link_3_u.dae" />
            </geometry>
            <material name="">
                <color rgba="0.12941176470588237 0.14901960784313725 0.7490196078431373 1.0" />
            </material>
        </visual>
        <collision>
            <geometry>
                <mesh filename="package://motoman_hc10_support/meshes/hc10/collision/link_3_u.stl" />
            </geometry>
        </collision>
    </link>
    <link name="link_4_r">
        
<inertial>
            <origin rpy="0 0 0" xyz="0 0 0" />
            <mass value="0.1" />
            <inertia ixx="0.03" ixy="0.03" ixz="0.03" iyy="0.0" iyz="0.0" izz="0.0" />
        </inertial>

        <visual>
            <geometry>
                <mesh filename="package://motoman_hc10_support/meshes/hc10/visual/link_4_r.dae" />
            </geometry>
            <material name="">
                <color rgba="0.12941176470588237 0.14901960784313725 0.7490196078431373 1.0" />
            </material>
        </visual>
        <collision>
            <geometry>
                <mesh filename="package://motoman_hc10_support/meshes/hc10/collision/link_4_r.stl" />
            </geometry>
        </collision>
    </link>
    <link name="link_5_b">
        
<inertial>
            <origin rpy="0 0 0" xyz="0 0 0" />
            <mass value="0.1" />
            <inertia ixx="0.03" ixy="0.03" ixz="0.03" iyy="0.0" iyz="0.0" izz="0.0" />
        </inertial>

        <visual>
            <geometry>
                <mesh filename="package://motoman_hc10_support/meshes/hc10/visual/link_5_b.dae" />
            </geometry>
            <material name="">
                <color rgba="0.12941176470588237 0.14901960784313725 0.7490196078431373 1.0" />
            </material>
        </visual>
        <collision>
            <geometry>
                <mesh filename="package://motoman_hc10_support/meshes/hc10/collision/link_5_b.stl" />
            </geometry>
        </collision>
    </link>
    <link name="link_6_t">
        
<inertial>
            <origin rpy="0 0 0" xyz="0 0 0" />
            <mass value="0.1" />
            <inertia ixx="0.03" ixy="0.03" ixz="0.03" iyy="0.0" iyz="0.0" izz="0.0" />
        </inertial>

        <visual>
            <geometry>
                <mesh filename="package://motoman_hc10_support/meshes/hc10/visual/link_6_t.dae" />
            </geometry>
            <material name="">
                <color rgba="0.12941176470588237 0.14901960784313725 0.7490196078431373 1.0" />
            </material>
        </visual>
        <collision>
            <geometry>
                <mesh filename="package://motoman_hc10_support/meshes/hc10/collision/link_6_t.stl" />
            </geometry>
        </collision>
    </link>
    <link name="tool0" />
    <!-- end of link list -->
    <!-- joint list -->
    <joint name="world_fixed" type="fixed">
        <parent link="world" />
        <child link="base_link" />
        <origin rpy="0 0 0" xyz="0.55 0.4 0.15" />
    </joint>
    <joint name="joint_1_s" type="revolute">
        <parent link="base_link" />
        <child link="link_1_s" />
        <origin rpy="0 0 0" xyz="0 0 0.275" />
        <axis xyz="0 0 1" />
        <limit effort="368.48" lower="-3.141592653589793" upper="3.141592653589793" velocity="2.2689280275926285" />
        <dynamics damping="1" />
    </joint>
    <joint name="joint_2_l" type="revolute">
        <parent link="link_1_s" />
        <child link="link_2_l" />
        <origin rpy="0 0 0" xyz="0 0 0" />
        <axis xyz="0 1 0" />
        <limit effort="368.48" lower="-3.141592653589793" upper="3.141592653589793" velocity="2.2689280275926285" />
        <dynamics damping="1" />
    </joint>
    <joint name="joint_3_u" type="revolute">
        <parent link="link_2_l" />
        <child link="link_3_u" />
        <origin rpy="0 0 0" xyz="0 0 0.700" />
        <axis xyz="0 -1 0" />
        <limit effort="141.12" lower="-0.08726646259971647" upper="6.19591884457987" velocity="3.141592653589793" />
        <dynamics damping="1" />
    </joint>
    <joint name="joint_4_r" type="revolute">
        <parent link="link_3_u" />
        <child link="link_4_r" />
        <origin rpy="0 0 0" xyz="0 0 -0.500" />
        <axis xyz="0 0 1" />
        <limit effort="39.20" lower="-3.141592653589793" upper="3.141592653589793" velocity="3.141592653589793" />
        <dynamics damping="1" />
    </joint>
    <joint name="joint_5_b" type="revolute">
        <parent link="link_4_r" />
        <child link="link_5_b" />
        <origin rpy="0 0 0" xyz="0 0.162 0" />
        <axis xyz="0 -1 0" />
        <limit effort="31.36" lower="-3.141592653589793" upper="3.141592653589793" velocity="4.363323129985824" />
        <dynamics damping="1" />
    </joint>
    <joint name="joint_6_t" type="revolute">
        <parent link="link_5_b" />
        <child link="link_6_t" />
        <origin rpy="0 0 0" xyz="0 0 0" />
        <axis xyz="0 0 1" />
        <limit effort="31.36" lower="-3.141592653589793" upper="3.141592653589793" velocity="4.363323129985824" />
        <dynamics damping="1" />
    </joint>
    <joint name="joint_6_t-tool0" type="fixed">
        <origin rpy="3.141592653589793 0 0" xyz="0 0 -0.130" />
        <parent link="link_6_t" />
        <child link="tool0" />
    </joint>
    <!-- end of joint list -->
    <gazebo reference="box_fixed">
        <material>Gazebo/Pedestrian</material>
        <mu1>0.2</mu1>
        <mu2>0.2</mu2>
    </gazebo>
    <gazebo reference="wall1">
        <material>Gazebo/Pedestrian</material>
        <mu1>0.2</mu1>
        <mu2>0.2</mu2>
    </gazebo>
    <gazebo reference="wall2">
        <material>Gazebo/Pedestrian</material>
        <mu1>0.2</mu1>
        <mu2>0.2</mu2>
    </gazebo>
    <gazebo reference="wall3">
        <material>Gazebo/Pedestrian</material>
        <mu1>0.2</mu1>
        <mu2>0.2</mu2>
    </gazebo>
    <gazebo reference="cardboard_box">
        <material>Gazebo/WoodFloor</material>
        <mu1>0.2</mu1>
        <mu2>0.2</mu2>
    </gazebo>
    <gazebo reference="base_link">
        <material>Gazebo/White</material>
        <mu1>0.2</mu1>
        <mu2>0.2</mu2>
    </gazebo>
    <gazebo reference="link_1_s">
        <material>Gazebo/White</material>
        <mu1>0.2</mu1>
        <mu2>0.2</mu2>
    </gazebo>
    <gazebo reference="link_2_l">
        <material>Gazebo/White</material>
        <mu1>0.2</mu1>
        <mu2>0.2</mu2>
    </gazebo>
    <gazebo reference="link_3_u">
        <material>Gazebo/White</material>
        <mu1>0.2</mu1>
        <mu2>0.2</mu2>
    </gazebo>
    <gazebo reference="link_4_r">
        <material>Gazebo/White</material>
        <mu1>0.2</mu1>
        <mu2>0.2</mu2>
    </gazebo>
    <gazebo reference="link_5_b">
        <material>Gazebo/White</material>
        <mu1>0.2</mu1>
        <mu2>0.2</mu2>
    </gazebo>
    <gazebo reference="link_6_t">
        <material>Gazebo/DarkMagentaTransparent</material>
        <mu1>0.2</mu1>
        <mu2>0.2</mu2>
    </gazebo>
    <transmission name="_tran_base">
        <type>transmission_interface/SimpleTransmission</type>
        <joint name="world_fixed">
            <hardwareInterface>hardware_interface/EffortJointInterface</hardwareInterface>
        </joint>
        <actuator name="_motor_base">
            <hardwareInterface>hardware_interface/EffortJointInterface</hardwareInterface>
            <mechanicalReduction>1</mechanicalReduction>
        </actuator>
    </transmission>
    <transmission name="_tran_1">
        <type>transmission_interface/SimpleTransmission</type>
        <joint name="joint_1_s">
            <hardwareInterface>hardware_interface/EffortJointInterface</hardwareInterface>
        </joint>
        <actuator name="_motor_1">
            <hardwareInterface>hardware_interface/EffortJointInterface</hardwareInterface>
            <mechanicalReduction>1</mechanicalReduction>
        </actuator>
    </transmission>
    <transmission name="_tran_2">
        <type>transmission_interface/SimpleTransmission</type>
        <joint name="joint_2_l">
            <hardwareInterface>hardware_interface/EffortJointInterface</hardwareInterface>
        </joint>
        <actuator name="_motor_2">
            <hardwareInterface>hardware_interface/EffortJointInterface</hardwareInterface>
            <mechanicalReduction>1</mechanicalReduction>
        </actuator>
    </transmission>
    <transmission name="_tran_3">
        <type>transmission_interface/SimpleTransmission</type>
        <joint name="joint_3_u">
            <hardwareInterface>hardware_interface/EffortJointInterface</hardwareInterface>
        </joint>
        <actuator name="_motor_3">
            <hardwareInterface>hardware_interface/EffortJointInterface</hardwareInterface>
            <mechanicalReduction>1</mechanicalReduction>
        </actuator>
    </transmission>
    <transmission name="_tran_4">
        <type>transmission_interface/SimpleTransmission</type>
        <joint name="joint_4_r">
            <hardwareInterface>hardware_interface/EffortJointInterface</hardwareInterface>
        </joint>
        <actuator name="_motor_4">
            <hardwareInterface>hardware_interface/EffortJointInterface</hardwareInterface>
            <mechanicalReduction>1</mechanicalReduction>
        </actuator>
    </transmission>
    <transmission name="_tran_5">
        <type>transmission_interface/SimpleTransmission</type>
        <joint name="joint_5_b">
            <hardwareInterface>hardware_interface/EffortJointInterface</hardwareInterface>
        </joint>
        <actuator name="_motor_5">
            <hardwareInterface>hardware_interface/EffortJointInterface</hardwareInterface>
            <mechanicalReduction>1</mechanicalReduction>
        </actuator>
    </transmission>
    <transmission name="_tran_6">
        <type>transmission_interface/SimpleTransmission</type>
        <joint name="joint_6_t">
            <hardwareInterface>hardware_interface/EffortJointInterface</hardwareInterface>
        </joint>
        <actuator name="_motor_6">
            <hardwareInterface>hardware_interface/EffortJointInterface</hardwareInterface>
            <mechanicalReduction>1</mechanicalReduction>
        </actuator>
    </transmission>
    <gazebo>
        <plugin filename="libgazebo_ros_control.so" name="gazebo_ros_control" />
    </gazebo>
    <!-- Définir le socle -->
    <link name="box">
        <visual>
            <origin rpy="0 0 0" xyz="0 0 0" />
            <geometry>
                <box size="1.5 1.5 0.15" />
            </geometry>
            <material name="blue">
                <color rgba="0.114 0.122 0.102 1" />
            </material>
        </visual>
        <collision>
            <origin rpy="0 0 0" xyz="0 0 0" />
            <geometry>
                <box size="1.5 1.5 0.15" />
            </geometry>
        </collision>
        
<inertial>
            <origin rpy="0 0 0" xyz="0 0 0" />
            <mass value="100" />
            <inertia ixx="1" ixy="0" ixz="0" iyy="1" iyz="0" izz="1" />
        </inertial>

    </link>
    <!-- Ajouter les parois  -->
    <link name="wall1">
        <visual>
            <origin rpy="0 0 0" xyz="0 0.7 0.825" />
            <geometry>
                <box size="1.3 0.1 1.5" />
            </geometry>
            <material name="glass">
                <color rgba="0.8 0.8 0.8 0.5" />
                <!-- Couleur transparente pour du verre -->
            </material>
        </visual>
        <collision>
            <origin rpy="0 0 0" xyz="0 0.7 0.825" />
            <geometry>
                <box size="1.5 0.1 1.5" />
            </geometry>
        </collision>
        
<inertial>
            <origin rpy="0 0 0" xyz="0 0.7 0.825" />
            <mass value="1" />
            <inertia ixx="1" ixy="0" ixz="0" iyy="1" iyz="0" izz="1" />
        </inertial>

    </link>
    <link name="wall2">
        <visual>
            <origin rpy="0 0 0" xyz="-0.7 0 0.825" />
            <geometry>
                <box size="0.1 1.5 1.5" />
            </geometry>
            <material name="glass">
                <color rgba="0.8 0.8 0.8 0.5" />
                <!-- Couleur transparente pour du verre -->
            </material>
        </visual>
        <collision>
            <origin rpy="0 0 0" xyz="-0.7 0 0.825" />
            <geometry>
                <box size="0.1 1.5 1.5" />
            </geometry>
        </collision>
        
<inertial>
            <origin rpy="0 0 0" xyz="-0.7 0 0.825" />
            <mass value="1" />
            <inertia ixx="1" ixy="0" ixz="0" iyy="1" iyz="0" izz="1" />
        </inertial>

    </link>
    <link name="wall3">
        <visual>
            <origin rpy="0 0 0" xyz="0.7 0 0.825" />
            <geometry>
                <box size="0.1 1.5 1.5" />
            </geometry>
            <material name="glass">
                <color rgba="0.8 0.8 0.8 0.5" />
                <!-- Couleur transparente pour du verre -->
            </material>
        </visual>
        <collision>
            <origin rpy="0 0 0" xyz="0.7 0 0.825" />
            <geometry>
                <box size="0.1 1.5 1.5" />
            </geometry>
        </collision>
        
<inertial>
            <origin rpy="0 0 0" xyz="0.7 0 0.825" />
            <mass value="1" />
            <inertia ixx="1" ixy="0" ixz="0" iyy="1" iyz="0" izz="1" />
        </inertial>

    </link>
    <!-- joint list pour le socle -->
    <joint name="box_fixed" type="revolute">
        <parent link="world" />
        <child link="box" />
        <origin rpy="0 0 0" xyz="0.75 0.75 0.075" />
        <dynamics damping="1" />
        <limit effort="10.0" lower="-3.14159" upper="3.14159" velocity="0.5" />
    </joint>
    <joint name="wall1_fixed" type="fixed">
        <parent link="box" />
        <child link="wall1" />
    </joint>
    <joint name="wall2_fixed" type="fixed">
        <parent link="box" />
        <child link="wall2" />
    </joint>
    <joint name="wall3_fixed" type="fixed">
        <parent link="box" />
        <child link="wall3" />
    </joint>
    <link name="cardboard_box">
        <visual>
            <origin rpy="0 0 0" xyz="0.4 0.15 0.15" />
            <geometry>
                <box size="0.2 0.2 0.2" />
            </geometry>
            <material name="cardboard">
                <color rgba="0.7 0.4 0.1 1.0" />
                <!-- Brown color for cardboard -->
            </material>
        </visual>
        <collision>
            <origin rpy="0 0 0" xyz="0.4 0.15 0.15" />
            <geometry>
                <box size="0.2 0.2 0.2" />
            </geometry>
        </collision>
        
<inertial>
            <origin rpy="0 0 0" xyz="0.4 0.15 0.15" />
            <mass value="1" />
            <inertia ixx="0.01" ixy="0" ixz="0" iyy="0.01" iyz="0" izz="0.01" />
        </inertial>

    </link>
    <!-- Define the joint to fix the box -->
    <joint name="cardboard_box_fixed" type="fixed">
        <parent link="box" />
        <child link="cardboard_box" />
    </joint>
    <transmission name="trans_joint_1_s">
        <type>transmission_interface/SimpleTransmission</type>
        <joint name="joint_1_s">
            <hardwareInterface>hardware_interface/EffortJointInterface</hardwareInterface>
        </joint>
        <actuator name="joint_1_s_motor">
            <hardwareInterface>hardware_interface/EffortJointInterface</hardwareInterface>
            <mechanicalReduction>1</mechanicalReduction>
        </actuator>
    </transmission>
    <transmission name="trans_joint_2_l">
        <type>transmission_interface/SimpleTransmission</type>
        <joint name="joint_2_l">
            <hardwareInterface>hardware_interface/EffortJointInterface</hardwareInterface>
        </joint>
        <actuator name="joint_2_l_motor">
            <hardwareInterface>hardware_interface/EffortJointInterface</hardwareInterface>
            <mechanicalReduction>1</mechanicalReduction>
        </actuator>
    </transmission>
    <transmission name="trans_joint_3_u">
        <type>transmission_interface/SimpleTransmission</type>
        <joint name="joint_3_u">
            <hardwareInterface>hardware_interface/EffortJointInterface</hardwareInterface>
        </joint>
        <actuator name="joint_3_u_motor">
            <hardwareInterface>hardware_interface/EffortJointInterface</hardwareInterface>
            <mechanicalReduction>1</mechanicalReduction>
        </actuator>
    </transmission>
    <transmission name="trans_joint_4_r">
        <type>transmission_interface/SimpleTransmission</type>
        <joint name="joint_4_r">
            <hardwareInterface>hardware_interface/EffortJointInterface</hardwareInterface>
        </joint>
        <actuator name="joint_4_r_motor">
            <hardwareInterface>hardware_interface/EffortJointInterface</hardwareInterface>
            <mechanicalReduction>1</mechanicalReduction>
        </actuator>
    </transmission>
    <transmission name="trans_joint_5_b">
        <type>transmission_interface/SimpleTransmission</type>
        <joint name="joint_5_b">
            <hardwareInterface>hardware_interface/EffortJointInterface</hardwareInterface>
        </joint>
        <actuator name="joint_5_b_motor">
            <hardwareInterface>hardware_interface/EffortJointInterface</hardwareInterface>
            <mechanicalReduction>1</mechanicalReduction>
        </actuator>
    </transmission>
    <transmission name="trans_joint_6_t">
        <type>transmission_interface/SimpleTransmission</type>
        <joint name="joint_6_t">
            <hardwareInterface>hardware_interface/EffortJointInterface</hardwareInterface>
        </joint>
        <actuator name="joint_6_t_motor">
            <hardwareInterface>hardware_interface/EffortJointInterface</hardwareInterface>
            <mechanicalReduction>1</mechanicalReduction>
        </actuator>
    </transmission>
    <transmission name="trans_box_fixed">
        <type>transmission_interface/SimpleTransmission</type>
        <joint name="box_fixed">
            <hardwareInterface>hardware_interface/EffortJointInterface</hardwareInterface>
        </joint>
        <actuator name="box_fixed_motor">
            <hardwareInterface>hardware_interface/EffortJointInterface</hardwareInterface>
            <mechanicalReduction>1</mechanicalReduction>
        </actuator>
    </transmission>
    <gazebo>
        <plugin name="gazebo_ros_control" filename="libgazebo_ros_control.so">
            <robotNamespace>/</robotNamespace>
        </plugin>
    </gazebo>
</robot>

<transmission name="_tran_base">
        <type>transmission_interface/SimpleTransmission</type>
        <joint name="world_fixed">
            <hardwareInterface>hardware_interface/EffortJointInterface</hardwareInterface>
        </joint>
        <actuator name="_motor_base">
            <hardwareInterface>hardware_interface/EffortJointInterface</hardwareInterface>
            <mechanicalReduction>1</mechanicalReduction>
        </actuator>
    </transmission>
    <transmission name="_tran_1">
        <type>transmission_interface/SimpleTransmission</type>
        <joint name="joint_1_s">
            <hardwareInterface>hardware_interface/EffortJointInterface</hardwareInterface>
        </joint>
        <actuator name="_motor_1">
            <hardwareInterface>hardware_interface/EffortJointInterface</hardwareInterface>
            <mechanicalReduction>1</mechanicalReduction>
        </actuator>
    </transmission>
    <transmission name="_tran_2">
        <type>transmission_interface/SimpleTransmission</type>
        <joint name="joint_2_l">
            <hardwareInterface>hardware_interface/EffortJointInterface</hardwareInterface>
        </joint>
        <actuator name="_motor_2">
            <hardwareInterface>hardware_interface/EffortJointInterface</hardwareInterface>
            <mechanicalReduction>1</mechanicalReduction>
        </actuator>
    </transmission>
    <transmission name="_tran_3">
        <type>transmission_interface/SimpleTransmission</type>
        <joint name="joint_3_u">
            <hardwareInterface>hardware_interface/EffortJointInterface</hardwareInterface>
        </joint>
        <actuator name="_motor_3">
            <hardwareInterface>hardware_interface/EffortJointInterface</hardwareInterface>
            <mechanicalReduction>1</mechanicalReduction>
        </actuator>
    </transmission>
    <transmission name="_tran_4">
        <type>transmission_interface/SimpleTransmission</type>
        <joint name="joint_4_r">
            <hardwareInterface>hardware_interface/EffortJointInterface</hardwareInterface>
        </joint>
        <actuator name="_motor_4">
            <hardwareInterface>hardware_interface/EffortJointInterface</hardwareInterface>
            <mechanicalReduction>1</mechanicalReduction>
        </actuator>
    </transmission>
    <transmission name="_tran_5">
        <type>transmission_interface/SimpleTransmission</type>
        <joint name="joint_5_b">
            <hardwareInterface>hardware_interface/EffortJointInterface</hardwareInterface>
        </joint>
        <actuator name="_motor_5">
            <hardwareInterface>hardware_interface/EffortJointInterface</hardwareInterface>
            <mechanicalReduction>1</mechanicalReduction>
        </actuator>
    </transmission>
    <transmission name="_tran_6">
        <type>transmission_interface/SimpleTransmission</type>
        <joint name="joint_6_t">
            <hardwareInterface>hardware_interface/EffortJointInterface</hardwareInterface>
        </joint>
        <actuator name="_motor_6">
            <hardwareInterface>hardware_interface/EffortJointInterface</hardwareInterface>
            <mechanicalReduction>1</mechanicalReduction>
        </actuator>
    </transmission>
    <gazebo>
        <plugin filename="libgazebo_ros_control.so" name="gazebo_ros_control" />
    </gazebo>
    <!-- Définir le socle -->
    <link name="box">
        <visual>
            <origin rpy="0 0 0" xyz="0 0 0" />
            <geometry>
                <box size="1.5 1.5 0.15" />
            </geometry>
            <material name="blue">
                <color rgba="0.114 0.122 0.102 1" />
            </material>
        </visual>
        <collision>
            <origin rpy="0 0 0" xyz="0 0 0" />
            <geometry>
                <box size="1.5 1.5 0.15" />
            </geometry>
        </collision>
        <inertial>
            <origin rpy="0 0 0" xyz="0 0 0" />
            <mass value="100" />
            <inertia ixx="1" ixy="0" ixz="0" iyy="1" iyz="0" izz="1" />
        </inertial>
    </link>
    <!-- Ajouter les parois  -->
    <link name="wall1">
        <visual>
            <origin rpy="0 0 0" xyz="0 0.7 0.825" />
            <geometry>
                <box size="1.3 0.1 1.5" />
            </geometry>
            <material name="glass">
                <color rgba="0.8 0.8 0.8 0.5" />
                <!-- Couleur transparente pour du verre -->
            </material>
        </visual>
        <collision>
            <origin rpy="0 0 0" xyz="0 0.7 0.825" />
            <geometry>
                <box size="1.5 0.1 1.5" />
            </geometry>
        </collision>
        <inertial>
            <origin rpy="0 0 0" xyz="0 0.7 0.825" />
            <mass value="1" />
            <inertia ixx="1" ixy="0" ixz="0" iyy="1" iyz="0" izz="1" />
        </inertial>
    </link>
    <link name="wall2">
        <visual>
            <origin rpy="0 0 0" xyz="-0.7 0 0.825" />
            <geometry>
                <box size="0.1 1.5 1.5" />
            </geometry>
            <material name="glass">
                <color rgba="0.8 0.8 0.8 0.5" />
                <!-- Couleur transparente pour du verre -->
            </material>
        </visual>
        <collision>
            <origin rpy="0 0 0" xyz="-0.7 0 0.825" />
            <geometry>
                <box size="0.1 1.5 1.5" />
            </geometry>
        </collision>
        <inertial>
            <origin rpy="0 0 0" xyz="-0.7 0 0.825" />
            <mass value="1" />
            <inertia ixx="1" ixy="0" ixz="0" iyy="1" iyz="0" izz="1" />
        </inertial>
    </link>
    <link name="wall3">
        <visual>
            <origin rpy="0 0 0" xyz="0.7 0 0.825" />
            <geometry>
                <box size="0.1 1.5 1.5" />
            </geometry>
            <material name="glass">
                <color rgba="0.8 0.8 0.8 0.5" />
                <!-- Couleur transparente pour du verre -->
            </material>
        </visual>
        <collision>
            <origin rpy="0 0 0" xyz="0.7 0 0.825" />
            <geometry>
                <box size="0.1 1.5 1.5" />
            </geometry>
        </collision>
        <inertial>
            <origin rpy="0 0 0" xyz="0.7 0 0.825" />
            <mass value="1" />
            <inertia ixx="1" ixy="0" ixz="0" iyy="1" iyz="0" izz="1" />
        </inertial>
    </link>
    <!-- joint list pour le socle -->
    <joint name="box_fixed" type="revolute">
        <parent link="world" />
        <child link="box" />
        <origin rpy="0 0 0" xyz="0.75 0.75 0.075" />
        <dynamics damping="1" />
        <limit effort="10.0" lower="-3.14159" upper="3.14159" velocity="0.5" />
    </joint>
    <joint name="wall1_fixed" type="fixed">
        <parent link="box" />
        <child link="wall1" />
    </joint>
    <joint name="wall2_fixed" type="fixed">
        <parent link="box" />
        <child link="wall2" />
    </joint>
    <joint name="wall3_fixed" type="fixed">
        <parent link="box" />
        <child link="wall3" />
    </joint>
    <link name="cardboard_box">
        <visual>
            <origin rpy="0 0 0" xyz="0.4 0.15 0.15" />
            <geometry>
                <box size="0.2 0.2 0.2" />
            </geometry>
            <material name="cardboard">
                <color rgba="0.7 0.4 0.1 1.0" />
                <!-- Brown color for cardboard -->
            </material>
        </visual>
        <collision>
            <origin rpy="0 0 0" xyz="0.4 0.15 0.15" />
            <geometry>
                <box size="0.2 0.2 0.2" />
            </geometry>
        </collision>
        <inertial>
            <origin rpy="0 0 0" xyz="0.4 0.15 0.15" />
            <mass value="1" />
            <inertia ixx="0.01" ixy="0" ixz="0" iyy="0.01" iyz="0" izz="0.01" />
        </inertial>
    </link>
    <!-- Define the joint to fix the box -->
    <joint name="cardboard_box_fixed" type="fixed">
        <parent link="box" />
        <child link="cardboard_box" />
    </joint>
    <transmission name="trans_joint_1_s">
        <type>transmission_interface/SimpleTransmission</type>
        <joint name="joint_1_s">
            <hardwareInterface>hardware_interface/EffortJointInterface</hardwareInterface>
        </joint>
        <actuator name="joint_1_s_motor">
            <hardwareInterface>hardware_interface/EffortJointInterface</hardwareInterface>
            <mechanicalReduction>1</mechanicalReduction>
        </actuator>
    </transmission>
    <transmission name="trans_joint_2_l">
        <type>transmission_interface/SimpleTransmission</type>
        <joint name="joint_2_l">
            <hardwareInterface>hardware_interface/EffortJointInterface</hardwareInterface>
        </joint>
        <actuator name="joint_2_l_motor">
            <hardwareInterface>hardware_interface/EffortJointInterface</hardwareInterface>
            <mechanicalReduction>1</mechanicalReduction>
        </actuator>
    </transmission>
    <transmission name="trans_joint_3_u">
        <type>transmission_interface/SimpleTransmission</type>
        <joint name="joint_3_u">
            <hardwareInterface>hardware_interface/EffortJointInterface</hardwareInterface>
        </joint>
        <actuator name="joint_3_u_motor">
            <hardwareInterface>hardware_interface/EffortJointInterface</hardwareInterface>
            <mechanicalReduction>1</mechanicalReduction>
        </actuator>
    </transmission>
    <transmission name="trans_joint_4_r">
        <type>transmission_interface/SimpleTransmission</type>
        <joint name="joint_4_r">
            <hardwareInterface>hardware_interface/EffortJointInterface</hardwareInterface>
        </joint>
        <actuator name="joint_4_r_motor">
            <hardwareInterface>hardware_interface/EffortJointInterface</hardwareInterface>
            <mechanicalReduction>1</mechanicalReduction>
        </actuator>
    </transmission>
    <transmission name="trans_joint_5_b">
        <type>transmission_interface/SimpleTransmission</type>
        <joint name="joint_5_b">
            <hardwareInterface>hardware_interface/EffortJointInterface</hardwareInterface>
        </joint>
        <actuator name="joint_5_b_motor">
            <hardwareInterface>hardware_interface/EffortJointInterface</hardwareInterface>
            <mechanicalReduction>1</mechanicalReduction>
        </actuator>
    </transmission>
    <transmission name="trans_joint_6_t">
        <type>transmission_interface/SimpleTransmission</type>
        <joint name="joint_6_t">
            <hardwareInterface>hardware_interface/EffortJointInterface</hardwareInterface>
        </joint>
        <actuator name="joint_6_t_motor">
            <hardwareInterface>hardware_interface/EffortJointInterface</hardwareInterface>
            <mechanicalReduction>1</mechanicalReduction>
        </actuator>
    </transmission>
    <transmission name="trans_box_fixed">
        <type>transmission_interface/SimpleTransmission</type>
        <joint name="box_fixed">
            <hardwareInterface>hardware_interface/EffortJointInterface</hardwareInterface>
        </joint>
        <actuator name="box_fixed_motor">
            <hardwareInterface>hardware_interface/EffortJointInterface</hardwareInterface>
            <mechanicalReduction>1</mechanicalReduction>
        </actuator>
    </transmission>
    <gazebo>
        <plugin name="gazebo_ros_control" filename="libgazebo_ros_control.so">
            <robotNamespace>/</robotNamespace>
        </plugin>
    </gazebo>
</robot>
